Workbook

Sheet README
A1: Daily Gold Reconciliation System
A2: All data in this workbook is synthetic. Rates are illustrative.
A5: WHAT THIS SOLVES
A6: A retail jeweller holds the same metal in four places at once: on the shelf, with karigars (goldsmiths) being worked into finished pieces, in scrap awaiting melt, and in old gold taken in part-exchange from customers.
A7: Each sits at a different purity. 10 grams of 22K is not 10 grams of 24K. Adding gross weights together produces a number that means nothing, which is why shops that count in gross weight cannot tell a genuine loss from a purity mix shift.
A8: Every quantity here is converted to FINE GOLD before anything is added or compared. Fine gold = gross weight x purity. On that basis every figure in the workbook is directly comparable.
A10: THE THREE QUESTIONS IT ANSWERS EVERY DAY
A11: 1. Does counted physical stock match the book? Variance is shown in grams fine and in rupees, against a tolerance set in Setup.
A12: 2. Is the shop's board rate still tracking the market? A board rate left stale while spot moves means metal is sold below replacement cost on every ticket.
A13: 3. How much making charge is being given away? List making charge versus realised, by day and by month. This is the most commonly unmeasured leak in the P&L.
A15: SHEETS
A16: Setup Purities, wastage norms by trade, variance and rate tolerances. Yellow cells are the ones to edit.
... A27: Weights in grams to three decimals. Fine gold reference purity is set in Setup.

Sheet Setup
A1: Setup
A2: Yellow cells are inputs. Everything else reads from here.
A4: Shop reference
A5: Business name | B5: Sample Jeweller (illustrative)
A6: Reporting currency | B6: INR
A7: Fine gold reference purity | B7: 0.995
A9: Purity table
A10: Karat | B10: Purity
A11: 24K | B11: 0.995
A12: 22K | B12: 0.916
A13: 18K | B13: 0.75
A14: 14K | B14: 0.585
A17: Wastage norm by trade | D17: Fraction of fine gold issued that may be lost in working.
A18: Trade | B18: Norm %
A19: Chain making | B19: 0.018
A20: Stone setting | B20: 0.035
A21: Casting | B21: 0.025
A22: Hand finishing | B22: 0.028
A24: Tolerances
A25: Stock variance tolerance (g fine) | B25: 2 | D25: Above this, the day is flagged for investigation.
A26: Board rate drift tolerance (₹/g fine) | B26: 150 | D26: Board rate allowed to sit this far from spot before repricing.
A27: Making charge realisation floor | B27: 0.85 | D27: Below this, discounting is flagged.
A30: Source: all values above are illustrative defaults chosen for this sample. Replace with the shop's own norms before use.

Sheet Rate_Sheet
A1: Rate Sheet
A2: Spot vs the shop's own board rate. Drift is the signal to reprice.
A4: Date | B4: Month | C4: Spot 24K (₹/10g) | D4: Spot fine (₹/g) | E4: Board rate 22K (₹/g) | F4: Board implied fine (₹/g) | G4: Drift (₹/g fine) | H4: Status
A5: 46296 | B5: =TEXT(A5,"YYYY-MM") -> 2026-10 | C5: 91978 | D5: =C5/10 -> 9197.8 | E5: 8445.35 | F5: =E5/INDEX(Setup!$B$11:$B$14,MATCH("22K",Setup!$A$11:$A$14,0)) -> 9219.8144 | G5: =F5-D5 -> 22.01441 | H5: =IF(ABS(G5)>Setup!$B$26,IF(G5<0,"REPRICE UP","REPRICE DOWN"),"OK") -> OK
A6: 46297 | B6: =TEXT(A6,"YYYY-MM") -> 2026-10 | C6: 93487 | D6: =C6/10 -> 9348.7 | E6: 8445.35 | F6: =E6/INDEX(Setup!$B$11:$B$14,MATCH("22K",Setup!$A$11:$A$14,0)) -> 9219.8144 | G6: =F6-D6 -> -128.88559 | H6: =IF(ABS(G6)>Setup!$B$26,IF(G6<0,"REPRICE UP","REPRICE DOWN"),"OK") -> OK
A7: 46298 | B7: =TEXT(A7,"YYYY-MM") -> 2026-10 | C7: 94054 | D7: =C7/10 -> 9405.4 | E7: 8445.35 | F7: =E7/INDEX(Setup!$B$11:$B$14,MATCH("22K",Setup!$A$11:$A$14,0)) -> 9219.8144 | G7: =F7-D7 -> -185.58559 | H7: =IF(ABS(G7)>Setup!$B$26,IF(G7<0,"REPRICE UP","REPRICE DOWN"),"OK") -> REPRICE UP
A8: 46300 | B8: =TEXT(A8,"YYYY-MM") -> 2026-10 | C8: 94227 | D8: =C8/10 -> 9422.7 | E8: 8445.35 | F8: =E8/INDEX(Setup!$B$11:$B$14,MATCH("22K",Setup!$A$11:$A$14,0)) -> 9219.8144 | G8: =F8-D8 -> -202.88559 | H8: =IF(ABS(G8)>Setup!$B$26,IF(G8<0,"REPRICE UP","REPRICE DOWN"),"OK") -> REPRICE UP
A9: 46301 | B9: =TEXT(A9,"YYYY-MM") -> 2026-10 | C9: 95178 | D9: =C9/10 -> 9517.8 | E9: 8721.2 | F9: =E9/INDEX(Setup!$B$11:$B$14,MATCH("22K",Setup!$A$11:$A$14,0)) -> 9520.9607 | G9: =F9-D9 -> 3.1606987 | H9: =IF(ABS(G9)>Setup!$B$26,IF(G9<0,"REPRICE UP","REPRICE DOWN"),"OK") -> OK
A10: 46302 | B10: =TEXT(A10,"YYYY-MM") -> 2026-10 | C10: 96205 | D10: =C10/10 -> 9620.5 | E10: 8721.2 | F10: =E10/INDEX(Setup!$B$11:$B$14,MATCH("22K",Setup!$A$11:$A$14,0)) -> 9520.9607 | G10: =F10-D10 -> -99.539301 | H10: =IF(ABS(G10)>Setup!$B$26,IF(G10<0,"REPRICE UP","REPRICE DOWN"),"OK") -> OK
A11: 46303 | B11: =TEXT(A11,"YYYY-MM") -> 2026-10 | C11: 96762 | D11: =C11/10 -> 9676.2 | E11: 8721.2 | F11: =E11/INDEX(Setup!$B$11:$B$14,MATCH("22K",Setup!$A$11:$A$14,0)) -> 9520.9607 | G11: =F11-D11 -> -155.2393 | H11: =IF(ABS(G11)>Setup!$B$26,IF(G11<0,"REPRICE UP","REPRICE DOWN"),"OK") -> REPRICE UP
A12: 46304 | B12: =TEXT(A12,"YYYY-MM") -> 2026-10 | C12: 97644 | D12: =C12/10 -> 9764.4 | E12: 8721.2 | F12: =E12/INDEX(Setup!$B$11:$B$14,MATCH("22K",Setup!$A$11:$A$14,0)) -> 9520.9607 | G12: =F12-D12 -> -243.4393 | H12: =IF(ABS(G12)>Setup!$B$26,IF(G12<0,"REPRICE UP","REPRICE DOWN"),"OK") -> REPRICE UP
A13: 46305 | B13: =TEXT(A13,"YYYY-MM") -> 2026-10 | C13: 96579 | D13: =C13/10 -> 9657.9 | E13: 8861.78 | F13: =E13/INDEX(Setup!$B$11:$B$14,MATCH("22K",Setup!$A$11:$A$14,0)) -> 9674.4323 | G13: =F13-D13 -> 16.532314 | H13: =IF(ABS(G13)>Setup!$B$26,IF(G13<0,"REPRICE UP","REPRICE DOWN"),"OK") -> OK
A14: 46307 | B14: =TEXT(A14,"YYYY-MM") -> 2026-10 | C14: 96123 | D14: =C14/10 -> 9612.3 | E14: 8861.78 | F14: =E14/INDEX(Setup!$B$11:$B$14,MATCH("22K",Setup!$A$11:$A$14,0)) -> 9674.4323 | G14: =F14-D14 -> 62.132314 | H14: =IF(ABS(G14)>Setup!$B$26,IF(G14<0,"REPRICE UP","REPRICE DOWN"),"OK") -> OK
A15: 46308 | B15: =TEXT(A15,"YYYY-MM") -> 2026-10 | C15: 96279 | D15: =C15/10 -> 9627.9 | E15: 8861.78 | F15: =E15/INDEX(Setup!$B$11:$B$14,MATCH("22K",Setup!$A$11:$A$14,0)) -> 9674.4323 | G15: =F15-D15 -> 46.532314 | H15: =IF(ABS(G15)>Setup!$B$26,IF(G15<0,"REPRICE UP","REPRICE DOWN"),"OK") -> OK
A16: 46309 | B16: =TEXT(A16,"YYYY-MM") -> 2026-10 | C16: 96128 | D16: =C16/10 -> 9612.8 | E16: 8861.78 | F16: =E16/INDEX(Setup!$B$11:$B$14,MATCH("22K",Setup!$A$11:$A$14,0)) -> 9674.4323 | G16: =F16-D16 -> 61.632314 | H16: =IF(ABS(G16)>Setup!$B$26,IF(G16<0,"REPRICE UP","REPRICE DOWN"),"OK") -> OK
... A26: 46321 | B26: =TEXT(A26,"YYYY-MM") -> 2026-10 | C26: 97692 | D26: =C26/10 -> 9769.2 | E26: 8864.11 | F26: =E26/INDEX(Setup!$B$11:$B$14,MATCH("22K",Setup!$A$11:$A$14,0)) -> 9676.976 | G26: =F26-D26 -> -92.224017 | H26: =IF(ABS(G26)>Setup!$B$26,IF(G26<0,"REPRICE UP","REPRICE DOWN"),"OK") -> OK
A28: Spot and board rates are synthetic. Board rate is reset every third day on purpose, to create the drift the recon is built to catch.

Sheet SKU_Register
A1: SKU Register
A2: Product master. Fine gold per piece is what the ledger consumes.
A4: SKU | B4: Category | C4: Karat | D4: Purity | E4: Gross wt (g) | F4: Stone wt (g) | G4: Net gold wt (g) | H4: Fine gold (g) | I4: MC basis | J4: MC rate | K4: MC list (₹)
A5: CH-1000 | B5: Chain | C5: 22K | D5: =INDEX(Setup!$B$11:$B$14,MATCH(C5,Setup!$A$11:$A$14,0)) -> 0.916 | E5: 27.563 | F5: 0 | G5: =E5-F5 -> 27.563 | H5: =G5*D5 -> 25.247708 | I5: Per gram | J5: 614 | K5: =IF(I5="Per gram",G5*J5,G5*D5*INDEX(Rate_Sheet!$D$5:$D$26,1)*J5) -> 16923.682
A6: BA-1001 | B6: Bangle | C6: 22K | D6: =INDEX(Setup!$B$11:$B$14,MATCH(C6,Setup!$A$11:$A$14,0)) -> 0.916 | E6: 26.934 | F6: 0 | G6: =E6-F6 -> 26.934 | H6: =G6*D6 -> 24.671544 | I6: Per gram | J6: 390 | K6: =IF(I6="Per gram",G6*J6,G6*D6*INDEX(Rate_Sheet!$D$5:$D$26,1)*J6) -> 10504.26
A7: RI-1002 | B7: Ring | C7: 22K | D7: =INDEX(Setup!$B$11:$B$14,MATCH(C7,Setup!$A$11:$A$14,0)) -> 0.916 | E7: 37.15 | F7: 4.179 | G7: =E7-F7 -> 32.971 | H7: =G7*D7 -> 30.201436 | I7: % of metal | J7: 0.1168 | K7: =IF(I7="Per gram",G7*J7,G7*D7*INDEX(Rate_Sheet!$D$5:$D$26,1)*J7) -> 32445.495
A8: NE-1003 | B8: Necklace | C8: 22K | D8: =INDEX(Setup!$B$11:$B$14,MATCH(C8,Setup!$A$11:$A$14,0)) -> 0.916 | E8: 40.969 | F8: 3.484 | G8: =E8-F8 -> 37.485 | H8: =G8*D8 -> 34.33626 | I8: % of metal | J8: 0.1599 | K8: =IF(I8="Per gram",G8*J8,G8*D8*INDEX(Rate_Sheet!$D$5:$D$26,1)*J8) -> 50499.307
A9: EA-1004 | B9: Earring | C9: 22K | D9: =INDEX(Setup!$B$11:$B$14,MATCH(C9,Setup!$A$11:$A$14,0)) -> 0.916 | E9: 32.475 | F9: 1.9 | G9: =E9-F9 -> 30.575 | H9: =G9*D9 -> 28.0067 | I9: % of metal | J9: 0.1068 | K9: =IF(I9="Per gram",G9*J9,G9*D9*INDEX(Rate_Sheet!$D$5:$D$26,1)*J9) -> 27511.683
A10: CH-1005 | B10: Chain | C10: 22K | D10: =INDEX(Setup!$B$11:$B$14,MATCH(C10,Setup!$A$11:$A$14,0)) -> 0.916 | E10: 26.609 | F10: 0 | G10: =E10-F10 -> 26.609 | H10: =G10*D10 -> 24.373844 | I10: Per gram | J10: 453 | K10: =IF(I10="Per gram",G10*J10,G10*D10*INDEX(Rate_Sheet!$D$5:$D$26,1)*J10) -> 12053.877
A11: BA-1006 | B11: Bangle | C11: 22K | D11: =INDEX(Setup!$B$11:$B$14,MATCH(C11,Setup!$A$11:$A$14,0)) -> 0.916 | E11: 8.207 | F11: 0 | G11: =E11-F11 -> 8.207 | H11: =G11*D11 -> 7.517612 | I11: Per gram | J11: 343 | K11: =IF(I11="Per gram",G11*J11,G11*D11*INDEX(Rate_Sheet!$D$5:$D$26,1)*J11) -> 2815.001
A12: RI-1007 | B12: Ring | C12: 18K | D12: =INDEX(Setup!$B$11:$B$14,MATCH(C12,Setup!$A$11:$A$14,0)) -> 0.75 | E12: 26.732 | F12: 3.245 | G12: =E12-F12 -> 23.487 | H12: =G12*D12 -> 17.61525 | I12: % of metal | J12: 0.1028 | K12: =IF(I12="Per gram",G12*J12,G12*D12*INDEX(Rate_Sheet!$D$5:$D$26,1)*J12) -> 16655.815
A13: NE-1008 | B13: Necklace | C13: 22K | D13: =INDEX(Setup!$B$11:$B$14,MATCH(C13,Setup!$A$11:$A$14,0)) -> 0.916 | E13: 30.987 | F13: 2.298 | G13: =E13-F13 -> 28.689 | H13: =G13*D13 -> 26.279124 | I13: % of metal | J13: 0.123 | K13: =IF(I13="Per gram",G13*J13,G13*D13*INDEX(Rate_Sheet!$D$5:$D$26,1)*J13) -> 29730.346
A14: EA-1009 | B14: Earring | C14: 22K | D14: =INDEX(Setup!$B$11:$B$14,MATCH(C14,Setup!$A$11:$A$14,0)) -> 0.916 | E14: 36.835 | F14: 2.179 | G14: =E14-F14 -> 34.656 | H14: =G14*D14 -> 31.744896 | I14: % of metal | J14: 0.1293 | K14: =IF(I14="Per gram",G14*J14,G14*D14*INDEX(Rate_Sheet!$D$5:$D$26,1)*J14) -> 37753.428
A15: CH-1010 | B15: Chain | C15: 22K | D15: =INDEX(Setup!$B$11:$B$14,MATCH(C15,Setup!$A$11:$A$14,0)) -> 0.916 | E15: 15.222 | F15: 0 | G15: =E15-F15 -> 15.222 | H15: =G15*D15 -> 13.943352 | I15: Per gram | J15: 400 | K15: =IF(I15="Per gram",G15*J15,G15*D15*INDEX(Rate_Sheet!$D$5:$D$26,1)*J15) -> 6088.8
A16: BA-1011 | B16: Bangle | C16: 22K | D16: =INDEX(Setup!$B$11:$B$14,MATCH(C16,Setup!$A$11:$A$14,0)) -> 0.916 | E16: 11.829 | F16: 0 | G16: =E16-F16 -> 11.829 | H16: =G16*D16 -> 10.835364 | I16: Per gram | J16: 521 | K16: =IF(I16="Per gram",G16*J16,G16*D16*INDEX(Rate_Sheet!$D$5:$D$26,1)*J16) -> 6162.909
... A22: RI-1017 | B22: Ring | C22: 22K | D22: =INDEX(Setup!$B$11:$B$14,MATCH(C22,Setup!$A$11:$A$14,0)) -> 0.916 | E22: 32.068 | F22: 2.378 | G22: =E22-F22 -> 29.69 | H22: =G22*D22 -> 27.19604 | I22: % of metal | J22: 0.1315 | K22: =IF(I22="Per gram",G22*J22,G22*D22*INDEX(Rate_Sheet!$D$5:$D$26,1)*J22) -> 32893.901

Sheet Karigar_Ledger
A1: Karigar Ledger
A2: Metal issued to goldsmiths, what returned, and wastage against the norm for the trade.
A4: Date | B4: Month | C4: Karigar | D4: Trade | E4: Karat | F4: Purity | G4: Issued gross (g) | H4: Issued fine (g) | I4: Returned finished gross (g) | J4: Returned fine (g) | K4: Scrap returned fine (g) | L4: Wastage fine (g) | M4: Wastage % | N4: Norm % | O4: vs Norm | P4: Status
A5: 46296 | B5: =TEXT(A5,"YYYY-MM") -> 2026-10 | C5: K-02 | D5: Chain making | E5: 22K | F5: =INDEX(Setup!$B$11:$B$14,MATCH(E5,Setup!$A$11:$A$14,0)) -> 0.916 | G5: 79.516 | H5: =G5*F5 -> 72.836656 | I5: 70.82 | J5: =I5*F5 -> 64.87112 | K5: 6.806 | L5: =H5-J5-K5 -> 1.159536 | M5: =IFERROR(L5/H5,0) -> 0.015919676 | N5: =INDEX(Setup!$B$19:$B$22,MATCH(D5,Setup!$A$19:$A$22,0)) -> 0.018 | O5: =M5-N5 -> -0.0020803235 | P5: =IF(O5>0.01,"OVER NORM",IF(O5<-0.005,"BELOW NORM","OK")) -> OK
A6: 46296 | B6: =TEXT(A6,"YYYY-MM") -> 2026-10 | C6: K-04 | D6: Casting | E6: 22K | F6: =INDEX(Setup!$B$11:$B$14,MATCH(E6,Setup!$A$11:$A$14,0)) -> 0.916 | G6: 60.679 | H6: =G6*F6 -> 55.581964 | I6: 55.623 | J6: =I6*F6 -> 50.950668 | K6: 3.292 | L6: =H6-J6-K6 -> 1.339296 | M6: =IFERROR(L6/H6,0) -> 0.024095874 | N6: =INDEX(Setup!$B$19:$B$22,MATCH(D6,Setup!$A$19:$A$22,0)) -> 0.025 | O6: =M6-N6 -> -0.00090412602 | P6: =IF(O6>0.01,"OVER NORM",IF(O6<-0.005,"BELOW NORM","OK")) -> OK
A7: 46297 | B7: =TEXT(A7,"YYYY-MM") -> 2026-10 | C7: K-04 | D7: Casting | E7: 22K | F7: =INDEX(Setup!$B$11:$B$14,MATCH(E7,Setup!$A$11:$A$14,0)) -> 0.916 | G7: 148.141 | H7: =G7*F7 -> 135.69716 | I7: 127.619 | J7: =I7*F7 -> 116.899 | K7: 14.991 | L7: =H7-J7-K7 -> 3.807152 | M7: =IFERROR(L7/H7,0) -> 0.02805624 | N7: =INDEX(Setup!$B$19:$B$22,MATCH(D7,Setup!$A$19:$A$22,0)) -> 0.025 | O7: =M7-N7 -> 0.0030562402 | P7: =IF(O7>0.01,"OVER NORM",IF(O7<-0.005,"BELOW NORM","OK")) -> OK
A8: 46297 | B8: =TEXT(A8,"YYYY-MM") -> 2026-10 | C8: K-05 | D8: Hand finishing | E8: 22K | F8: =INDEX(Setup!$B$11:$B$14,MATCH(E8,Setup!$A$11:$A$14,0)) -> 0.916 | G8: 84.17 | H8: =G8*F8 -> 77.09972 | I8: 74.077 | J8: =I8*F8 -> 67.854532 | K8: 7.07 | L8: =H8-J8-K8 -> 2.175188 | M8: =IFERROR(L8/H8,0) -> 0.028212658 | N8: =INDEX(Setup!$B$19:$B$22,MATCH(D8,Setup!$A$19:$A$22,0)) -> 0.028 | O8: =M8-N8 -> 0.00021265758 | P8: =IF(O8>0.01,"OVER NORM",IF(O8<-0.005,"BELOW NORM","OK")) -> OK
A9: 46298 | B9: =TEXT(A9,"YYYY-MM") -> 2026-10 | C9: K-05 | D9: Hand finishing | E9: 22K | F9: =INDEX(Setup!$B$11:$B$14,MATCH(E9,Setup!$A$11:$A$14,0)) -> 0.916 | G9: 161.006 | H9: =G9*F9 -> 147.4815 | I9: 141.446 | J9: =I9*F9 -> 129.56454 | K9: 14.986 | L9: =H9-J9-K9 -> 2.93096 | M9: =IFERROR(L9/H9,0) -> 0.019873408 | N9: =INDEX(Setup!$B$19:$B$22,MATCH(D9,Setup!$A$19:$A$22,0)) -> 0.028 | O9: =M9-N9 -> -0.0081265916 | P9: =IF(O9>0.01,"OVER NORM",IF(O9<-0.005,"BELOW NORM","OK")) -> BELOW NORM
A10: 46298 | B10: =TEXT(A10,"YYYY-MM") -> 2026-10 | C10: K-01 | D10: Chain making | E10: 22K | F10: =INDEX(Setup!$B$11:$B$14,MATCH(E10,Setup!$A$11:$A$14,0)) -> 0.916 | G10: 137.94 | H10: =G10*F10 -> 126.35304 | I10: 120.132 | J10: =I10*F10 -> 110.04091 | K10: 13.945 | L10: =H10-J10-K10 -> 2.367128 | M10: =IFERROR(L10/H10,0) -> 0.018734239 | N10: =INDEX(Setup!$B$19:$B$22,MATCH(D10,Setup!$A$19:$A$22,0)) -> 0.018 | O10: =M10-N10 -> 0.00073423861 | P10: =IF(O10>0.01,"OVER NORM",IF(O10<-0.005,"BELOW NORM","OK")) -> OK
A11: 46298 | B11: =TEXT(A11,"YYYY-MM") -> 2026-10 | C11: K-03 | D11: Stone setting | E11: 22K | F11: =INDEX(Setup!$B$11:$B$14,MATCH(E11,Setup!$A$11:$A$14,0)) -> 0.916 | G11: 233.229 | H11: =G11*F11 -> 213.63776 | I11: 200.805 | J11: =I11*F11 -> 183.93738 | K11: 16.868 | L11: =H11-J11-K11 -> 12.832384 | M11: =IFERROR(L11/H11,0) -> 0.060066085 | N11: =INDEX(Setup!$B$19:$B$22,MATCH(D11,Setup!$A$19:$A$22,0)) -> 0.035 | O11: =M11-N11 -> 0.025066085 | P11: =IF(O11>0.01,"OVER NORM",IF(O11<-0.005,"BELOW NORM","OK")) -> OVER NORM
A12: 46300 | B12: =TEXT(A12,"YYYY-MM") -> 2026-10 | C12: K-04 | D12: Casting | E12: 22K | F12: =INDEX(Setup!$B$11:$B$14,MATCH(E12,Setup!$A$11:$A$14,0)) -> 0.916 | G12: 227.262 | H12: =G12*F12 -> 208.17199 | I12: 190.341 | J12: =I12*F12 -> 174.35236 | K12: 27.463 | L12: =H12-J12-K12 -> 6.356636 | M12: =IFERROR(L12/H12,0) -> 0.030535501 | N12: =INDEX(Setup!$B$19:$B$22,MATCH(D12,Setup!$A$19:$A$22,0)) -> 0.025 | O12: =M12-N12 -> 0.0055355007 | P12: =IF(O12>0.01,"OVER NORM",IF(O12<-0.005,"BELOW NORM","OK")) -> OK
A13: 46300 | B13: =TEXT(A13,"YYYY-MM") -> 2026-10 | C13: K-02 | D13: Chain making | E13: 22K | F13: =INDEX(Setup!$B$11:$B$14,MATCH(E13,Setup!$A$11:$A$14,0)) -> 0.916 | G13: 234.437 | H13: =G13*F13 -> 214.74429 | I13: 217.121 | J13: =I13*F13 -> 198.88284 | K13: 12.755 | L13: =H13-J13-K13 -> 3.106456 | M13: =IFERROR(L13/H13,0) -> 0.014465837 | N13: =INDEX(Setup!$B$19:$B$22,MATCH(D13,Setup!$A$19:$A$22,0)) -> 0.018 | O13: =M13-N13 -> -0.0035341626 | P13: =IF(O13>0.01,"OVER NORM",IF(O13<-0.005,"BELOW NORM","OK")) -> OK
A14: 46300 | B14: =TEXT(A14,"YYYY-MM") -> 2026-10 | C14: K-03 | D14: Stone setting | E14: 22K | F14: =INDEX(Setup!$B$11:$B$14,MATCH(E14,Setup!$A$11:$A$14,0)) -> 0.916 | G14: 97.196 | H14: =G14*F14 -> 89.031536 | I14: 83.355 | J14: =I14*F14 -> 76.35318 | K14: 7.428 | L14: =H14-J14-K14 -> 5.250356 | M14: =IFERROR(L14/H14,0) -> 0.058971868 | N14: =INDEX(Setup!$B$19:$B$22,MATCH(D14,Setup!$A$19:$A$22,0)) -> 0.035 | O14: =M14-N14 -> 0.023971868 | P14: =IF(O14>0.01,"OVER NORM",IF(O14<-0.005,"BELOW NORM","OK")) -> OVER NORM
A15: 46301 | B15: =TEXT(A15,"YYYY-MM") -> 2026-10 | C15: K-05 | D15: Hand finishing | E15: 22K | F15: =INDEX(Setup!$B$11:$B$14,MATCH(E15,Setup!$A$11:$A$14,0)) -> 0.916 | G15: 124.308 | H15: =G15*F15 -> 113.86613 | I15: 103.376 | J15: =I15*F15 -> 94.692416 | K15: 15.213 | L15: =H15-J15-K15 -> 3.960712 | M15: =IFERROR(L15/H15,0) -> 0.034783935 | N15: =INDEX(Setup!$B$19:$B$22,MATCH(D15,Setup!$A$19:$A$22,0)) -> 0.028 | O15: =M15-N15 -> 0.006783935 | P15: =IF(O15>0.01,"OVER NORM",IF(O15<-0.005,"BELOW NORM","OK")) -> OK
A16: 46301 | B16: =TEXT(A16,"YYYY-MM") -> 2026-10 | C16: K-03 | D16: Stone setting | E16: 22K | F16: =INDEX(Setup!$B$11:$B$14,MATCH(E16,Setup!$A$11:$A$14,0)) -> 0.916 | G16: 99.208 | H16: =G16*F16 -> 90.874528 | I16: 85.605 | J16: =I16*F16 -> 78.41418 | K16: 7.505 | L16: =H16-J16-K16 -> 4.955348 | M16: =IFERROR(L16/H16,0) -> 0.05452956 | N16: =INDEX(Setup!$B$19:$B$22,MATCH(D16,Setup!$A$19:$A$22,0)) -> 0.035 | O16: =M16-N16 -> 0.01952956 | P16: =IF(O16>0.01,"OVER NORM",IF(O16<-0.005,"BELOW NORM","OK")) -> OVER NORM
... A56: 46321 | B56: =TEXT(A56,"YYYY-MM") -> 2026-10 | C56: K-03 | D56: Stone setting | E56: 22K | F56: =INDEX(Setup!$B$11:$B$14,MATCH(E56,Setup!$A$11:$A$14,0)) -> 0.916 | G56: 175.548 | H56: =G56*F56 -> 160.80197 | I56: 143.02 | J56: =I56*F56 -> 131.00632 | K56: 21.005 | L56: =H56-J56-K56 -> 8.790648 | M56: =IFERROR(L56/H56,0) -> 0.05466754 | N56: =INDEX(Setup!$B$19:$B$22,MATCH(D56,Setup!$A$19:$A$22,0)) -> 0.035 | O56: =M56-N56 -> 0.01966754 | P56: =IF(O56>0.01,"OVER NORM",IF(O56<-0.005,"BELOW NORM","OK")) -> OVER NORM

Sheet Sales_Register
A1: Sales Register
A2: Line-level sales. Making charge list vs realised is the leakage measure.
A4: Date | B4: Month | C4: Invoice | D4: SKU | E4: Qty | F4: Net gold wt (g) | G4: Fine gold (g) | H4: Rate applied (₹/g fine) | I4: Metal value (₹) | J4: MC list (₹) | K4: Discount % | L4: MC realised (₹) | M4: MC given away (₹) | N4: Old gold in fine (g) | O4: Old gold credit (₹) | P4: Net invoice (₹)
A5: 46296 | B5: =TEXT(A5,"YYYY-MM") -> 2026-10 | C5: INV-4101 | D5: EA-1014 | E5: 1 | F5: =E5*INDEX(SKU_Register!$G$5:$G$22,MATCH(D5,SKU_Register!$A$5:$A$22,0)) -> 9.438 | G5: =E5*INDEX(SKU_Register!$H$5:$H$22,MATCH(D5,SKU_Register!$A$5:$A$22,0)) -> 8.645208 | H5: =Rate_Sheet!$F$5 -> 9219.8144 | I5: =G5*H5 -> 79707.213 | J5: =E5*INDEX(SKU_Register!$K$5:$K$22,MATCH(D5,SKU_Register!$A$5:$A$22,0)) -> 8810.4719 | K5: 0.25 | L5: =J5*(1-K5) -> 6607.8539 | M5: =J5-L5 -> 2202.618 | N5: 17.528 | O5: =N5*H5 -> 161604.91 | P5: =I5+L5-O5 -> -75289.84
A6: 46296 | B6: =TEXT(A6,"YYYY-MM") -> 2026-10 | C6: INV-4102 | D6: CH-1005 | E6: 1 | F6: =E6*INDEX(SKU_Register!$G$5:$G$22,MATCH(D6,SKU_Register!$A$5:$A$22,0)) -> 26.609 | G6: =E6*INDEX(SKU_Register!$H$5:$H$22,MATCH(D6,SKU_Register!$A$5:$A$22,0)) -> 24.373844 | H6: =Rate_Sheet!$F$5 -> 9219.8144 | I6: =G6*H6 -> 224722.32 | J6: =E6*INDEX(SKU_Register!$K$5:$K$22,MATCH(D6,SKU_Register!$A$5:$A$22,0)) -> 12053.877 | K6: 0.05 | L6: =J6*(1-K6) -> 11451.183 | M6: =J6-L6 -> 602.69385 | N6: 0 | O6: =N6*H6 -> 0 | P6: =I6+L6-O6 -> 236173.5
A7: 46297 | B7: =TEXT(A7,"YYYY-MM") -> 2026-10 | C7: INV-4103 | D7: BA-1006 | E7: 1 | F7: =E7*INDEX(SKU_Register!$G$5:$G$22,MATCH(D7,SKU_Register!$A$5:$A$22,0)) -> 8.207 | G7: =E7*INDEX(SKU_Register!$H$5:$H$22,MATCH(D7,SKU_Register!$A$5:$A$22,0)) -> 7.517612 | H7: =Rate_Sheet!$F$6 -> 9219.8144 | I7: =G7*H7 -> 69310.987 | J7: =E7*INDEX(SKU_Register!$K$5:$K$22,MATCH(D7,SKU_Register!$A$5:$A$22,0)) -> 2815.001 | K7: 0 | L7: =J7*(1-K7) -> 2815.001 | M7: =J7-L7 -> 0 | N7: 2.065 | O7: =N7*H7 -> 19038.917 | P7: =I7+L7-O7 -> 53087.072
A8: 46297 | B8: =TEXT(A8,"YYYY-MM") -> 2026-10 | C8: INV-4104 | D8: BA-1016 | E8: 1 | F8: =E8*INDEX(SKU_Register!$G$5:$G$22,MATCH(D8,SKU_Register!$A$5:$A$22,0)) -> 40.02 | G8: =E8*INDEX(SKU_Register!$H$5:$H$22,MATCH(D8,SKU_Register!$A$5:$A$22,0)) -> 36.65832 | H8: =Rate_Sheet!$F$6 -> 9219.8144 | I8: =G8*H8 -> 337982.91 | J8: =E8*INDEX(SKU_Register!$K$5:$K$22,MATCH(D8,SKU_Register!$A$5:$A$22,0)) -> 23451.72 | K8: 0.05 | L8: =J8*(1-K8) -> 22279.134 | M8: =J8-L8 -> 1172.586 | N8: 0 | O8: =N8*H8 -> 0 | P8: =I8+L8-O8 -> 360262.04
A9: 46297 | B9: =TEXT(A9,"YYYY-MM") -> 2026-10 | C9: INV-4105 | D9: BA-1006 | E9: 1 | F9: =E9*INDEX(SKU_Register!$G$5:$G$22,MATCH(D9,SKU_Register!$A$5:$A$22,0)) -> 8.207 | G9: =E9*INDEX(SKU_Register!$H$5:$H$22,MATCH(D9,SKU_Register!$A$5:$A$22,0)) -> 7.517612 | H9: =Rate_Sheet!$F$6 -> 9219.8144 | I9: =G9*H9 -> 69310.987 | J9: =E9*INDEX(SKU_Register!$K$5:$K$22,MATCH(D9,SKU_Register!$A$5:$A$22,0)) -> 2815.001 | K9: 0.25 | L9: =J9*(1-K9) -> 2111.2508 | M9: =J9-L9 -> 703.75025 | N9: 10.323 | O9: =N9*H9 -> 95176.144 | P9: =I9+L9-O9 -> -23753.906
A10: 46297 | B10: =TEXT(A10,"YYYY-MM") -> 2026-10 | C10: INV-4106 | D10: EA-1009 | E10: 1 | F10: =E10*INDEX(SKU_Register!$G$5:$G$22,MATCH(D10,SKU_Register!$A$5:$A$22,0)) -> 34.656 | G10: =E10*INDEX(SKU_Register!$H$5:$H$22,MATCH(D10,SKU_Register!$A$5:$A$22,0)) -> 31.744896 | H10: =Rate_Sheet!$F$6 -> 9219.8144 | I10: =G10*H10 -> 292682.05 | J10: =E10*INDEX(SKU_Register!$K$5:$K$22,MATCH(D10,SKU_Register!$A$5:$A$22,0)) -> 37753.428 | K10: 0.2 | L10: =J10*(1-K10) -> 30202.743 | M10: =J10-L10 -> 7550.6857 | N10: 16.052 | O10: =N10*H10 -> 147996.46 | P10: =I10+L10-O10 -> 174888.33
A11: 46298 | B11: =TEXT(A11,"YYYY-MM") -> 2026-10 | C11: INV-4107 | D11: CH-1000 | E11: 1 | F11: =E11*INDEX(SKU_Register!$G$5:$G$22,MATCH(D11,SKU_Register!$A$5:$A$22,0)) -> 27.563 | G11: =E11*INDEX(SKU_Register!$H$5:$H$22,MATCH(D11,SKU_Register!$A$5:$A$22,0)) -> 25.247708 | H11: =Rate_Sheet!$F$7 -> 9219.8144 | I11: =G11*H11 -> 232779.18 | J11: =E11*INDEX(SKU_Register!$K$5:$K$22,MATCH(D11,SKU_Register!$A$5:$A$22,0)) -> 16923.682 | K11: 0.1 | L11: =J11*(1-K11) -> 15231.314 | M11: =J11-L11 -> 1692.3682 | N11: 16.579 | O11: =N11*H11 -> 152855.3 | P11: =I11+L11-O11 -> 95155.193
A12: 46298 | B12: =TEXT(A12,"YYYY-MM") -> 2026-10 | C12: INV-4108 | D12: EA-1009 | E12: 2 | F12: =E12*INDEX(SKU_Register!$G$5:$G$22,MATCH(D12,SKU_Register!$A$5:$A$22,0)) -> 69.312 | G12: =E12*INDEX(SKU_Register!$H$5:$H$22,MATCH(D12,SKU_Register!$A$5:$A$22,0)) -> 63.489792 | H12: =Rate_Sheet!$F$7 -> 9219.8144 | I12: =G12*H12 -> 585364.1 | J12: =E12*INDEX(SKU_Register!$K$5:$K$22,MATCH(D12,SKU_Register!$A$5:$A$22,0)) -> 75506.857 | K12: 0.3 | L12: =J12*(1-K12) -> 52854.8 | M12: =J12-L12 -> 22652.057 | N12: 0 | O12: =N12*H12 -> 0 | P12: =I12+L12-O12 -> 638218.9
A13: 46298 | B13: =TEXT(A13,"YYYY-MM") -> 2026-10 | C13: INV-4109 | D13: RI-1012 | E13: 2 | F13: =E13*INDEX(SKU_Register!$G$5:$G$22,MATCH(D13,SKU_Register!$A$5:$A$22,0)) -> 25.12 | G13: =E13*INDEX(SKU_Register!$H$5:$H$22,MATCH(D13,SKU_Register!$A$5:$A$22,0)) -> 18.84 | H13: =Rate_Sheet!$F$7 -> 9219.8144 | I13: =G13*H13 -> 173701.3 | J13: =E13*INDEX(SKU_Register!$K$5:$K$22,MATCH(D13,SKU_Register!$A$5:$A$22,0)) -> 19321.451 | K13: 0.1 | L13: =J13*(1-K13) -> 17389.305 | M13: =J13-L13 -> 1932.1451 | N13: 0 | O13: =N13*H13 -> 0 | P13: =I13+L13-O13 -> 191090.61
A14: 46300 | B14: =TEXT(A14,"YYYY-MM") -> 2026-10 | C14: INV-4110 | D14: BA-1001 | E14: 1 | F14: =E14*INDEX(SKU_Register!$G$5:$G$22,MATCH(D14,SKU_Register!$A$5:$A$22,0)) -> 26.934 | G14: =E14*INDEX(SKU_Register!$H$5:$H$22,MATCH(D14,SKU_Register!$A$5:$A$22,0)) -> 24.671544 | H14: =Rate_Sheet!$F$8 -> 9219.8144 | I14: =G14*H14 -> 227467.06 | J14: =E14*INDEX(SKU_Register!$K$5:$K$22,MATCH(D14,SKU_Register!$A$5:$A$22,0)) -> 10504.26 | K14: 0.05 | L14: =J14*(1-K14) -> 9979.047 | M14: =J14-L14 -> 525.213 | N14: 0 | O14: =N14*H14 -> 0 | P14: =I14+L14-O14 -> 237446.1
A15: 46300 | B15: =TEXT(A15,"YYYY-MM") -> 2026-10 | C15: INV-4111 | D15: EA-1014 | E15: 1 | F15: =E15*INDEX(SKU_Register!$G$5:$G$22,MATCH(D15,SKU_Register!$A$5:$A$22,0)) -> 9.438 | G15: =E15*INDEX(SKU_Register!$H$5:$H$22,MATCH(D15,SKU_Register!$A$5:$A$22,0)) -> 8.645208 | H15: =Rate_Sheet!$F$8 -> 9219.8144 | I15: =G15*H15 -> 79707.213 | J15: =E15*INDEX(SKU_Register!$K$5:$K$22,MATCH(D15,SKU_Register!$A$5:$A$22,0)) -> 8810.4719 | K15: 0.2 | L15: =J15*(1-K15) -> 7048.3775 | M15: =J15-L15 -> 1762.0944 | N15: 11.521 | O15: =N15*H15 -> 106221.48 | P15: =I15+L15-O15 -> -19465.891
A16: 46300 | B16: =TEXT(A16,"YYYY-MM") -> 2026-10 | C16: INV-4112 | D16: CH-1000 | E16: 1 | F16: =E16*INDEX(SKU_Register!$G$5:$G$22,MATCH(D16,SKU_Register!$A$5:$A$22,0)) -> 27.563 | G16: =E16*INDEX(SKU_Register!$H$5:$H$22,MATCH(D16,SKU_Register!$A$5:$A$22,0)) -> 25.247708 | H16: =Rate_Sheet!$F$8 -> 9219.8144 | I16: =G16*H16 -> 232779.18 | J16: =E16*INDEX(SKU_Register!$K$5:$K$22,MATCH(D16,SKU_Register!$A$5:$A$22,0)) -> 16923.682 | K16: 0.15 | L16: =J16*(1-K16) -> 14385.13 | M16: =J16-L16 -> 2538.5523 | N16: 0 | O16: =N16*H16 -> 0 | P16: =I16+L16-O16 -> 247164.31
A17: 46300 | B17: =TEXT(A17,"YYYY-MM") -> 2026-10 | C17: INV-4113 | D17: NE-1013 | E17: 1 | F17: =E17*INDEX(SKU_Register!$G$5:$G$22,MATCH(D17,SKU_Register!$A$5:$A$22,0)) -> 13.001 | G17: =E17*INDEX(SKU_Register!$H$5:$H$22,MATCH(D17,SKU_Register!$A$5:$A$22,0)) -> 11.908916 | H17: =Rate_Sheet!$F$8 -> 9219.8144 | I17: =G17*H17 -> 109798 | J17: =E17*INDEX(SKU_Register!$K$5:$K$22,MATCH(D17,SKU_Register!$A$5:$A$22,0)) -> 14480.636 | K17: 0 | L17: =J17*(1-K17) -> 14480.636 | M17: =J17-L17 -> 0 | N17: 0 | O17: =N17*H17 -> 0 | P17: =I17+L17-O17 -> 124278.63
A18: 46301 | B18: =TEXT(A18,"YYYY-MM") -> 2026-10 | C18: INV-4114 | D18: BA-1011 | E18: 1 | F18: =E18*INDEX(SKU_Register!$G$5:$G$22,MATCH(D18,SKU_Register!$A$5:$A$22,0)) -> 11.829 | G18: =E18*INDEX(SKU_Register!$H$5:$H$22,MATCH(D18,SKU_Register!$A$5:$A$22,0)) -> 10.835364 | H18: =Rate_Sheet!$F$9 -> 9520.9607 | I18: =G18*H18 -> 103163.07 | J18: =E18*INDEX(SKU_Register!$K$5:$K$22,MATCH(D18,SKU_Register!$A$5:$A$22,0)) -> 6162.909 | K18: 0.05 | L18: =J18*(1-K18) -> 5854.7635 | M18: =J18-L18 -> 308.14545 | N18: 0 | O18: =N18*H18 -> 0 | P18: =I18+L18-O18 -> 109017.84
A19: 46301 | B19: =TEXT(A19,"YYYY-MM") -> 2026-10 | C19: INV-4115 | D19: NE-1008 | E19: 1 | F19: =E19*INDEX(SKU_Register!$G$5:$G$22,MATCH(D19,SKU_Register!$A$5:$A$22,0)) -> 28.689 | G19: =E19*INDEX(SKU_Register!$H$5:$H$22,MATCH(D19,SKU_Register!$A$5:$A$22,0)) -> 26.279124 | H19: =Rate_Sheet!$F$9 -> 9520.9607 | I19: =G19*H19 -> 250202.51 | J19: =E19*INDEX(SKU_Register!$K$5:$K$22,MATCH(D19,SKU_Register!$A$5:$A$22,0)) -> 29730.346 | K19: 0.05 | L19: =J19*(1-K19) -> 28243.828 | M19: =J19-L19 -> 1486.5173 | N19: 4.223 | O19: =N19*H19 -> 40207.017 | P19: =I19+L19-O19 -> 238239.32
A20: 46301 | B20: =TEXT(A20,"YYYY-MM") -> 2026-10 | C20: INV-4116 | D20: BA-1011 | E20: 1 | F20: =E20*INDEX(SKU_Register!$G$5:$G$22,MATCH(D20,SKU_Register!$A$5:$A$22,0)) -> 11.829 | G20: =E20*INDEX(SKU_Register!$H$5:$H$22,MATCH(D20,SKU_Register!$A$5:$A$22,0)) -> 10.835364 | H20: =Rate_Sheet!$F$9 -> 9520.9607 | I20: =G20*H20 -> 103163.07 | J20: =E20*INDEX(SKU_Register!$K$5:$K$22,MATCH(D20,SKU_Register!$A$5:$A$22,0)) -> 6162.909 | K20: 0.1 | L20: =J20*(1-K20) -> 5546.6181 | M20: =J20-L20 -> 616.2909 | N20: 0 | O20: =N20*H20 -> 0 | P20: =I20+L20-O20 -> 108709.69
A21: 46302 | B21: =TEXT(A21,"YYYY-MM") -> 2026-10 | C21: INV-4117 | D21: BA-1011 | E21: 1 | F21: =E21*INDEX(SKU_Register!$G$5:$G$22,MATCH(D21,SKU_Register!$A$5:$A$22,0)) -> 11.829 | G21: =E21*INDEX(SKU_Register!$H$5:$H$22,MATCH(D21,SKU_Register!$A$5:$A$22,0)) -> 10.835364 | H21: =Rate_Sheet!$F$10 -> 9520.9607 | I21: =G21*H21 -> 103163.07 | J21: =E21*INDEX(SKU_Register!$K$5:$K$22,MATCH(D21,SKU_Register!$A$5:$A$22,0)) -> 6162.909 | K21: 0 | L21: =J21*(1-K21) -> 6162.909 | M21: =J21-L21 -> 0 | N21: 0 | O21: =N21*H21 -> 0 | P21: =I21+L21-O21 -> 109325.98
A22: 46302 | B22: =TEXT(A22,"YYYY-MM") -> 2026-10 | C22: INV-4118 | D22: CH-1015 | E22: 1 | F22: =E22*INDEX(SKU_Register!$G$5:$G$22,MATCH(D22,SKU_Register!$A$5:$A$22,0)) -> 5.71 | G22: =E22*INDEX(SKU_Register!$H$5:$H$22,MATCH(D22,SKU_Register!$A$5:$A$22,0)) -> 5.23036 | H22: =Rate_Sheet!$F$10 -> 9520.9607 | I22: =G22*H22 -> 49798.052 | J22: =E22*INDEX(SKU_Register!$K$5:$K$22,MATCH(D22,SKU_Register!$A$5:$A$22,0)) -> 2289.71 | K22: 0.05 | L22: =J22*(1-K22) -> 2175.2245 | M22: =J22-L22 -> 114.4855 | N22: 0 | O22: =N22*H22 -> 0 | P22: =I22+L22-O22 -> 51973.276
A23: 46302 | B23: =TEXT(A23,"YYYY-MM") -> 2026-10 | C23: INV-4119 | D23: RI-1007 | E23: 1 | F23: =E23*INDEX(SKU_Register!$G$5:$G$22,MATCH(D23,SKU_Register!$A$5:$A$22,0)) -> 23.487 | G23: =E23*INDEX(SKU_Register!$H$5:$H$22,MATCH(D23,SKU_Register!$A$5:$A$22,0)) -> 17.61525 | H23: =Rate_Sheet!$F$10 -> 9520.9607 | I23: =G23*H23 -> 167714.1 | J23: =E23*INDEX(SKU_Register!$K$5:$K$22,MATCH(D23,SKU_Register!$A$5:$A$22,0)) -> 16655.815 | K23: 0.25 | L23: =J23*(1-K23) -> 12491.861 | M23: =J23-L23 -> 4163.9537 | N23: 2.085 | O23: =N23*H23 -> 19851.203 | P23: =I23+L23-O23 -> 160354.76
A24: 46303 | B24: =TEXT(A24,"YYYY-MM") -> 2026-10 | C24: INV-4120 | D24: EA-1014 | E24: 1 | F24: =E24*INDEX(SKU_Register!$G$5:$G$22,MATCH(D24,SKU_Register!$A$5:$A$22,0)) -> 9.438 | G24: =E24*INDEX(SKU_Register!$H$5:$H$22,MATCH(D24,SKU_Register!$A$5:$A$22,0)) -> 8.645208 | H24: =Rate_Sheet!$F$11 -> 9520.9607 | I24: =G24*H24 -> 82310.686 | J24: =E24*INDEX(SKU_Register!$K$5:$K$22,MATCH(D24,SKU_Register!$A$5:$A$22,0)) -> 8810.4719 | K24: 0 | L24: =J24*(1-K24) -> 8810.4719 | M24: =J24-L24 -> 0 | N24: 0 | O24: =N24*H24 -> 0 | P24: =I24+L24-O24 -> 91121.157
A25: 46303 | B25: =TEXT(A25,"YYYY-MM") -> 2026-10 | C25: INV-4121 | D25: BA-1011 | E25: 1 | F25: =E25*INDEX(SKU_Register!$G$5:$G$22,MATCH(D25,SKU_Register!$A$5:$A$22,0)) -> 11.829 | G25: =E25*INDEX(SKU_Register!$H$5:$H$22,MATCH(D25,SKU_Register!$A$5:$A$22,0)) -> 10.835364 | H25: =Rate_Sheet!$F$11 -> 9520.9607 | I25: =G25*H25 -> 103163.07 | J25: =E25*INDEX(SKU_Register!$K$5:$K$22,MATCH(D25,SKU_Register!$A$5:$A$22,0)) -> 6162.909 | K25: 0 | L25: =J25*(1-K25) -> 6162.909 | M25: =J25-L25 -> 0 | N25: 0.248 | O25: =N25*H25 -> 2361.1983 | P25: =I25+L25-O25 -> 106964.79
A26: 46303 | B26: =TEXT(A26,"YYYY-MM") -> 2026-10 | C26: INV-4122 | D26: BA-1016 | E26: 1 | F26: =E26*INDEX(SKU_Register!$G$5:$G$22,MATCH(D26,SKU_Register!$A$5:$A$22,0)) -> 40.02 | G26: =E26*INDEX(SKU_Register!$H$5:$H$22,MATCH(D26,SKU_Register!$A$5:$A$22,0)) -> 36.65832 | H26: =Rate_Sheet!$F$11 -> 9520.9607 | I26: =G26*H26 -> 349022.42 | J26: =E26*INDEX(SKU_Register!$K$5:$K$22,MATCH(D26,SKU_Register!$A$5:$A$22,0)) -> 23451.72 | K26: 0.1 | L26: =J26*(1-K26) -> 21106.548 | M26: =J26-L26 -> 2345.172 | N26: 0 | O26: =N26*H26 -> 0 | P26: =I26+L26-O26 -> 370128.97
A27: 46303 | B27: =TEXT(A27,"YYYY-MM") -> 2026-10 | C27: INV-4123 | D27: CH-1005 | E27: 2 | F27: =E27*INDEX(SKU_Register!$G$5:$G$22,MATCH(D27,SKU_Register!$A$5:$A$22,0)) -> 53.218 | G27: =E27*INDEX(SKU_Register!$H$5:$H$22,MATCH(D27,SKU_Register!$A$5:$A$22,0)) -> 48.747688 | H27: =Rate_Sheet!$F$11 -> 9520.9607 | I27: =G27*H27 -> 464124.82 | J27: =E27*INDEX(SKU_Register!$K$5:$K$22,MATCH(D27,SKU_Register!$A$5:$A$22,0)) -> 24107.754 | K27: 0.2 | L27: =J27*(1-K27) -> 19286.203 | M27: =J27-L27 -> 4821.5508 | N27: 0 | O27: =N27*H27 -> 0 | P27: =I27+L27-O27 -> 483411.02
A28: 46304 | B28: =TEXT(A28,"YYYY-MM") -> 2026-10 | C28: INV-4124 | D28: RI-1017 | E28: 1 | F28: =E28*INDEX(SKU_Register!$G$5:$G$22,MATCH(D28,SKU_Register!$A$5:$A$22,0)) -> 29.69 | G28: =E28*INDEX(SKU_Register!$H$5:$H$22,MATCH(D28,SKU_Register!$A$5:$A$22,0)) -> 27.19604 | H28: =Rate_Sheet!$F$12 -> 9520.9607 | I28: =G28*H28 -> 258932.43 | J28: =E28*INDEX(SKU_Register!$K$5:$K$22,MATCH(D28,SKU_Register!$A$5:$A$22,0)) -> 32893.901 | K28: 0.15 | L28: =J28*(1-K28) -> 27959.816 | M28: =J28-L28 -> 4934.0852 | N28: 0 | O28: =N28*H28 -> 0 | P28: =I28+L28-O28 -> 286892.24
A29: 46304 | B29: =TEXT(A29,"YYYY-MM") -> 2026-10 | C29: INV-4125 | D29: CH-1005 | E29: 1 | F29: =E29*INDEX(SKU_Register!$G$5:$G$22,MATCH(D29,SKU_Register!$A$5:$A$22,0)) -> 26.609 | G29: =E29*INDEX(SKU_Register!$H$5:$H$22,MATCH(D29,SKU_Register!$A$5:$A$22,0)) -> 24.373844 | H29: =Rate_Sheet!$F$12 -> 9520.9607 | I29: =G29*H29 -> 232062.41 | J29: =E29*INDEX(SKU_Register!$K$5:$K$22,MATCH(D29,SKU_Register!$A$5:$A$22,0)) -> 12053.877 | K29: 0.2 | L29: =J29*(1-K29) -> 9643.1016 | M29: =J29-L29 -> 2410.7754 | N29: 0 | O29: =N29*H29 -> 0 | P29: =I29+L29-O29 -> 241705.51
A30: 46304 | B30: =TEXT(A30,"YYYY-MM") -> 2026-10 | C30: INV-4126 | D30: EA-1004 | E30: 2 | F30: =E30*INDEX(SKU_Register!$G$5:$G$22,MATCH(D30,SKU_Register!$A$5:$A$22,0)) -> 61.15 | G30: =E30*INDEX(SKU_Register!$H$5:$H$22,MATCH(D30,SKU_Register!$A$5:$A$22,0)) -> 56.0134 | H30: =Rate_Sheet!$F$12 -> 9520.9607 | I30: =G30*H30 -> 533301.38 | J30: =E30*INDEX(SKU_Register!$K$5:$K$22,MATCH(D30,SKU_Register!$A$5:$A$22,0)) -> 55023.365 | K30: 0.1 | L30: =J30*(1-K30) -> 49521.029 | M30: =J30-L30 -> 5502.3365 | N30: 0 | O30: =N30*H30 -> 0 | P30: =I30+L30-O30 -> 582822.41
A31: 46305 | B31: =TEXT(A31,"YYYY-MM") -> 2026-10 | C31: INV-4127 | D31: RI-1017 | E31: 1 | F31: =E31*INDEX(SKU_Register!$G$5:$G$22,MATCH(D31,SKU_Register!$A$5:$A$22,0)) -> 29.69 | G31: =E31*INDEX(SKU_Register!$H$5:$H$22,MATCH(D31,SKU_Register!$A$5:$A$22,0)) -> 27.19604 | H31: =Rate_Sheet!$F$13 -> 9674.4323 | I31: =G31*H31 -> 263106.25 | J31: =E31*INDEX(SKU_Register!$K$5:$K$22,MATCH(D31,SKU_Register!$A$5:$A$22,0)) -> 32893.901 | K31: 0.2 | L31: =J31*(1-K31) -> 26315.121 | M31: =J31-L31 -> 6578.7803 | N31: 0 | O31: =N31*H31 -> 0 | P31: =I31+L31-O31 -> 289421.37
A32: 46305 | B32: =TEXT(A32,"YYYY-MM") -> 2026-10 | C32: INV-4128 | D32: RI-1002 | E32: 2 | F32: =E32*INDEX(SKU_Register!$G$5:$G$22,MATCH(D32,SKU_Register!$A$5:$A$22,0)) -> 65.942 | G32: =E32*INDEX(SKU_Register!$H$5:$H$22,MATCH(D32,SKU_Register!$A$5:$A$22,0)) -> 60.402872 | H32: =Rate_Sheet!$F$13 -> 9674.4323 | I32: =G32*H32 -> 584363.5 | J32: =E32*INDEX(SKU_Register!$K$5:$K$22,MATCH(D32,SKU_Register!$A$5:$A$22,0)) -> 64890.989 | K32: 0.15 | L32: =J32*(1-K32) -> 55157.341 | M32: =J32-L32 -> 9733.6484 | N32: 0 | O32: =N32*H32 -> 0 | P32: =I32+L32-O32 -> 639520.84
A33: 46305 | B33: =TEXT(A33,"YYYY-MM") -> 2026-10 | C33: INV-4129 | D33: EA-1004 | E33: 1 | F33: =E33*INDEX(SKU_Register!$G$5:$G$22,MATCH(D33,SKU_Register!$A$5:$A$22,0)) -> 30.575 | G33: =E33*INDEX(SKU_Register!$H$5:$H$22,MATCH(D33,SKU_Register!$A$5:$A$22,0)) -> 28.0067 | H33: =Rate_Sheet!$F$13 -> 9674.4323 | I33: =G33*H33 -> 270948.92 | J33: =E33*INDEX(SKU_Register!$K$5:$K$22,MATCH(D33,SKU_Register!$A$5:$A$22,0)) -> 27511.683 | K33: 0.3 | L33: =J33*(1-K33) -> 19258.178 | M33: =J33-L33 -> 8253.5048 | N33: 0 | O33: =N33*H33 -> 0 | P33: =I33+L33-O33 -> 290207.1
A34: 46307 | B34: =TEXT(A34,"YYYY-MM") -> 2026-10 | C34: INV-4130 | D34: CH-1015 | E34: 1 | F34: =E34*INDEX(SKU_Register!$G$5:$G$22,MATCH(D34,SKU_Register!$A$5:$A$22,0)) -> 5.71 | G34: =E34*INDEX(SKU_Register!$H$5:$H$22,MATCH(D34,SKU_Register!$A$5:$A$22,0)) -> 5.23036 | H34: =Rate_Sheet!$F$14 -> 9674.4323 | I34: =G34*H34 -> 50600.764 | J34: =E34*INDEX(SKU_Register!$K$5:$K$22,MATCH(D34,SKU_Register!$A$5:$A$22,0)) -> 2289.71 | K34: 0.3 | L34: =J34*(1-K34) -> 1602.797 | M34: =J34-L34 -> 686.913 | N34: 12.268 | O34: =N34*H34 -> 118685.94 | P34: =I34+L34-O34 -> -66482.375
A35: 46307 | B35: =TEXT(A35,"YYYY-MM") -> 2026-10 | C35: INV-4131 | D35: RI-1012 | E35: 2 | F35: =E35*INDEX(SKU_Register!$G$5:$G$22,MATCH(D35,SKU_Register!$A$5:$A$22,0)) -> 25.12 | G35: =E35*INDEX(SKU_Register!$H$5:$H$22,MATCH(D35,SKU_Register!$A$5:$A$22,0)) -> 18.84 | H35: =Rate_Sheet!$F$14 -> 9674.4323 | I35: =G35*H35 -> 182266.3 | J35: =E35*INDEX(SKU_Register!$K$5:$K$22,MATCH(D35,SKU_Register!$A$5:$A$22,0)) -> 19321.451 | K35: 0.25 | L35: =J35*(1-K35) -> 14491.088 | M35: =J35-L35 -> 4830.3626 | N35: 13.65 | O35: =N35*H35 -> 132056 | P35: =I35+L35-O35 -> 64701.392
A36: 46307 | B36: =TEXT(A36,"YYYY-MM") -> 2026-10 | C36: INV-4132 | D36: RI-1017 | E36: 1 | F36: =E36*INDEX(SKU_Register!$G$5:$G$22,MATCH(D36,SKU_Register!$A$5:$A$22,0)) -> 29.69 | G36: =E36*INDEX(SKU_Register!$H$5:$H$22,MATCH(D36,SKU_Register!$A$5:$A$22,0)) -> 27.19604 | H36: =Rate_Sheet!$F$14 -> 9674.4323 | I36: =G36*H36 -> 263106.25 | J36: =E36*INDEX(SKU_Register!$K$5:$K$22,MATCH(D36,SKU_Register!$A$5:$A$22,0)) -> 32893.901 | K36: 0.2 | L36: =J36*(1-K36) -> 26315.121 | M36: =J36-L36 -> 6578.7803 | N36: 0 | O36: =N36*H36 -> 0 | P36: =I36+L36-O36 -> 289421.37
A37: 46308 | B37: =TEXT(A37,"YYYY-MM") -> 2026-10 | C37: INV-4133 | D37: RI-1007 | E37: 2 | F37: =E37*INDEX(SKU_Register!$G$5:$G$22,MATCH(D37,SKU_Register!$A$5:$A$22,0)) -> 46.974 | G37: =E37*INDEX(SKU_Register!$H$5:$H$22,MATCH(D37,SKU_Register!$A$5:$A$22,0)) -> 35.2305 | H37: =Rate_Sheet!$F$15 -> 9674.4323 | I37: =G37*H37 -> 340835.09 | J37: =E37*INDEX(SKU_Register!$K$5:$K$22,MATCH(D37,SKU_Register!$A$5:$A$22,0)) -> 33311.63 | K37: 0 | L37: =J37*(1-K37) -> 33311.63 | M37: =J37-L37 -> 0 | N37: 0 | O37: =N37*H37 -> 0 | P37: =I37+L37-O37 -> 374146.72
A38: 46308 | B38: =TEXT(A38,"YYYY-MM") -> 2026-10 | C38: INV-4134 | D38: CH-1010 | E38: 1 | F38: =E38*INDEX(SKU_Register!$G$5:$G$22,MATCH(D38,SKU_Register!$A$5:$A$22,0)) -> 15.222 | G38: =E38*INDEX(SKU_Register!$H$5:$H$22,MATCH(D38,SKU_Register!$A$5:$A$22,0)) -> 13.943352 | H38: =Rate_Sheet!$F$15 -> 9674.4323 | I38: =G38*H38 -> 134894.02 | J38: =E38*INDEX(SKU_Register!$K$5:$K$22,MATCH(D38,SKU_Register!$A$5:$A$22,0)) -> 6088.8 | K38: 0.2 | L38: =J38*(1-K38) -> 4871.04 | M38: =J38-L38 -> 1217.76 | N38: 0 | O38: =N38*H38 -> 0 | P38: =I38+L38-O38 -> 139765.06
A39: 46308 | B39: =TEXT(A39,"YYYY-MM") -> 2026-10 | C39: INV-4135 | D39: BA-1001 | E39: 2 | F39: =E39*INDEX(SKU_Register!$G$5:$G$22,MATCH(D39,SKU_Register!$A$5:$A$22,0)) -> 53.868 | G39: =E39*INDEX(SKU_Register!$H$5:$H$22,MATCH(D39,SKU_Register!$A$5:$A$22,0)) -> 49.343088 | H39: =Rate_Sheet!$F$15 -> 9674.4323 | I39: =G39*H39 -> 477366.37 | J39: =E39*INDEX(SKU_Register!$K$5:$K$22,MATCH(D39,SKU_Register!$A$5:$A$22,0)) -> 21008.52 | K39: 0.25 | L39: =J39*(1-K39) -> 15756.39 | M39: =J39-L39 -> 5252.13 | N39: 0 | O39: =N39*H39 -> 0 | P39: =I39+L39-O39 -> 493122.76
A40: 46309 | B40: =TEXT(A40,"YYYY-MM") -> 2026-10 | C40: INV-4136 | D40: NE-1008 | E40: 1 | F40: =E40*INDEX(SKU_Register!$G$5:$G$22,MATCH(D40,SKU_Register!$A$5:$A$22,0)) -> 28.689 | G40: =E40*INDEX(SKU_Register!$H$5:$H$22,MATCH(D40,SKU_Register!$A$5:$A$22,0)) -> 26.279124 | H40: =Rate_Sheet!$F$16 -> 9674.4323 | I40: =G40*H40 -> 254235.61 | J40: =E40*INDEX(SKU_Register!$K$5:$K$22,MATCH(D40,SKU_Register!$A$5:$A$22,0)) -> 29730.346 | K40: 0.2 | L40: =J40*(1-K40) -> 23784.276 | M40: =J40-L40 -> 5946.0691 | N40: 0 | O40: =N40*H40 -> 0 | P40: =I40+L40-O40 -> 278019.88
A41: 46309 | B41: =TEXT(A41,"YYYY-MM") -> 2026-10 | C41: INV-4137 | D41: CH-1000 | E41: 1 | F41: =E41*INDEX(SKU_Register!$G$5:$G$22,MATCH(D41,SKU_Register!$A$5:$A$22,0)) -> 27.563 | G41: =E41*INDEX(SKU_Register!$H$5:$H$22,MATCH(D41,SKU_Register!$A$5:$A$22,0)) -> 25.247708 | H41: =Rate_Sheet!$F$16 -> 9674.4323 | I41: =G41*H41 -> 244257.24 | J41: =E41*INDEX(SKU_Register!$K$5:$K$22,MATCH(D41,SKU_Register!$A$5:$A$22,0)) -> 16923.682 | K41: 0 | L41: =J41*(1-K41) -> 16923.682 | M41: =J41-L41 -> 0 | N41: 0 | O41: =N41*H41 -> 0 | P41: =I41+L41-O41 -> 261180.92
...

Sheet Metal_Ledger
A1: Metal Ledger
A2: Everything on a fine gold basis, so shelf, karigar and scrap metal are comparable.
A4: Date | B4: Month | C4: Opening book (g fine) | D4: Purchases (g fine) | E4: Issued to karigar (g fine) | F4: Received from karigar (g fine) | G4: Sold (g fine) | H4: Old gold taken in (g fine) | I4: Closing book (g fine) | J4: Physical counted (g fine) | K4: Variance (g fine) | L4: Variance (₹) | M4: Tolerance (g) | N4: Status
A5: 46296 | B5: =TEXT(A5,"YYYY-MM") -> 2026-10 | C5: 1820 | D5: 81.875 | E5: =SUMIFS(Karigar_Ledger!$H$5:$H$56,Karigar_Ledger!$A$5:$A$56,A5) -> 128.41862 | F5: =SUMIFS(Karigar_Ledger!$J$5:$J$56,Karigar_Ledger!$A$5:$A$56,A5)+SUMIFS(Karigar_Ledger!$K$5:$K$56,Karigar_Ledger!$A$5:$A$56,A5) -> 125.91979 | G5: =SUMIFS(Sales_Register!$G$5:$G$72,Sales_Register!$A$5:$A$72,A5) -> 33.019052 | H5: =SUMIFS(Sales_Register!$N$5:$N$72,Sales_Register!$A$5:$A$72,A5) -> 17.528 | I5: =C5+D5-E5+F5-G5+H5 -> 1883.8851 | J5: =I5+-0.5 -> 1883.3851 | K5: =J5-I5 -> -0.5 | L5: =K5*Rate_Sheet!$D$5 -> -4598.9 | M5: =Setup!$B$25 -> 2 | N5: =IF(ABS(K5)>M5,"INVESTIGATE","OK") -> OK
A6: 46297 | B6: =TEXT(A6,"YYYY-MM") -> 2026-10 | C6: =I5 -> 1883.8851 | D6: 0 | E6: =SUMIFS(Karigar_Ledger!$H$5:$H$56,Karigar_Ledger!$A$5:$A$56,A6) -> 212.79688 | F6: =SUMIFS(Karigar_Ledger!$J$5:$J$56,Karigar_Ledger!$A$5:$A$56,A6)+SUMIFS(Karigar_Ledger!$K$5:$K$56,Karigar_Ledger!$A$5:$A$56,A6) -> 206.81454 | G6: =SUMIFS(Sales_Register!$G$5:$G$72,Sales_Register!$A$5:$A$72,A6) -> 83.43844 | H6: =SUMIFS(Sales_Register!$N$5:$N$72,Sales_Register!$A$5:$A$72,A6) -> 28.44 | I6: =C6+D6-E6+F6-G6+H6 -> 1822.9043 | J6: =I6+-0.373 -> 1822.5313 | K6: =J6-I6 -> -0.373 | L6: =K6*Rate_Sheet!$D$6 -> -3487.0651 | M6: =Setup!$B$25 -> 2 | N6: =IF(ABS(K6)>M6,"INVESTIGATE","OK") -> OK
A7: 46298 | B7: =TEXT(A7,"YYYY-MM") -> 2026-10 | C7: =I6 -> 1822.9043 | D7: 0 | E7: =SUMIFS(Karigar_Ledger!$H$5:$H$56,Karigar_Ledger!$A$5:$A$56,A7) -> 487.4723 | F7: =SUMIFS(Karigar_Ledger!$J$5:$J$56,Karigar_Ledger!$A$5:$A$56,A7)+SUMIFS(Karigar_Ledger!$K$5:$K$56,Karigar_Ledger!$A$5:$A$56,A7) -> 469.34183 | G7: =SUMIFS(Sales_Register!$G$5:$G$72,Sales_Register!$A$5:$A$72,A7) -> 107.5775 | H7: =SUMIFS(Sales_Register!$N$5:$N$72,Sales_Register!$A$5:$A$72,A7) -> 16.579 | I7: =C7+D7-E7+F7-G7+H7 -> 1713.7754 | J7: =I7+0.558 -> 1714.3334 | K7: =J7-I7 -> 0.558 | L7: =K7*Rate_Sheet!$D$7 -> 5248.2132 | M7: =Setup!$B$25 -> 2 | N7: =IF(ABS(K7)>M7,"INVESTIGATE","OK") -> OK
A8: 46300 | B8: =TEXT(A8,"YYYY-MM") -> 2026-10 | C8: =I7 -> 1713.7754 | D8: 152.127 | E8: =SUMIFS(Karigar_Ledger!$H$5:$H$56,Karigar_Ledger!$A$5:$A$56,A8) -> 511.94782 | F8: =SUMIFS(Karigar_Ledger!$J$5:$J$56,Karigar_Ledger!$A$5:$A$56,A8)+SUMIFS(Karigar_Ledger!$K$5:$K$56,Karigar_Ledger!$A$5:$A$56,A8) -> 497.23437 | G8: =SUMIFS(Sales_Register!$G$5:$G$72,Sales_Register!$A$5:$A$72,A8) -> 70.473376 | H8: =SUMIFS(Sales_Register!$N$5:$N$72,Sales_Register!$A$5:$A$72,A8) -> 11.521 | I8: =C8+D8-E8+F8-G8+H8 -> 1792.2365 | J8: =I8+-3.42 -> 1788.8165 | K8: =J8-I8 -> -3.42 | L8: =K8*Rate_Sheet!$D$8 -> -32225.634 | M8: =Setup!$B$25 -> 2 | N8: =IF(ABS(K8)>M8,"INVESTIGATE","OK") -> INVESTIGATE
A9: 46301 | B9: =TEXT(A9,"YYYY-MM") -> 2026-10 | C9: =I8 -> 1792.2365 | D9: 0 | E9: =SUMIFS(Karigar_Ledger!$H$5:$H$56,Karigar_Ledger!$A$5:$A$56,A9) -> 374.35638 | F9: =SUMIFS(Karigar_Ledger!$J$5:$J$56,Karigar_Ledger!$A$5:$A$56,A9)+SUMIFS(Karigar_Ledger!$K$5:$K$56,Karigar_Ledger!$A$5:$A$56,A9) -> 362.36816 | G9: =SUMIFS(Sales_Register!$G$5:$G$72,Sales_Register!$A$5:$A$72,A9) -> 47.949852 | H9: =SUMIFS(Sales_Register!$N$5:$N$72,Sales_Register!$A$5:$A$72,A9) -> 4.223 | I9: =C9+D9-E9+F9-G9+H9 -> 1736.5215 | J9: =I9+0.573 -> 1737.0945 | K9: =J9-I9 -> 0.573 | L9: =K9*Rate_Sheet!$D$9 -> 5453.6994 | M9: =Setup!$B$25 -> 2 | N9: =IF(ABS(K9)>M9,"INVESTIGATE","OK") -> OK
A10: 46302 | B10: =TEXT(A10,"YYYY-MM") -> 2026-10 | C10: =I9 -> 1736.5215 | D10: 0 | E10: =SUMIFS(Karigar_Ledger!$H$5:$H$56,Karigar_Ledger!$A$5:$A$56,A10) -> 255.76735 | F10: =SUMIFS(Karigar_Ledger!$J$5:$J$56,Karigar_Ledger!$A$5:$A$56,A10)+SUMIFS(Karigar_Ledger!$K$5:$K$56,Karigar_Ledger!$A$5:$A$56,A10) -> 244.51567 | G10: =SUMIFS(Sales_Register!$G$5:$G$72,Sales_Register!$A$5:$A$72,A10) -> 33.680974 | H10: =SUMIFS(Sales_Register!$N$5:$N$72,Sales_Register!$A$5:$A$72,A10) -> 2.085 | I10: =C10+D10-E10+F10-G10+H10 -> 1693.6738 | J10: =I10+0.189 -> 1693.8628 | K10: =J10-I10 -> 0.189 | L10: =K10*Rate_Sheet!$D$10 -> 1818.2745 | M10: =Setup!$B$25 -> 2 | N10: =IF(ABS(K10)>M10,"INVESTIGATE","OK") -> OK
A11: 46303 | B11: =TEXT(A11,"YYYY-MM") -> 2026-10 | C11: =I10 -> 1693.6738 | D11: 0 | E11: =SUMIFS(Karigar_Ledger!$H$5:$H$56,Karigar_Ledger!$A$5:$A$56,A11) -> 376.35784 | F11: =SUMIFS(Karigar_Ledger!$J$5:$J$56,Karigar_Ledger!$A$5:$A$56,A11)+SUMIFS(Karigar_Ledger!$K$5:$K$56,Karigar_Ledger!$A$5:$A$56,A11) -> 360.01807 | G11: =SUMIFS(Sales_Register!$G$5:$G$72,Sales_Register!$A$5:$A$72,A11) -> 104.88658 | H11: =SUMIFS(Sales_Register!$N$5:$N$72,Sales_Register!$A$5:$A$72,A11) -> 0.248 | I11: =C11+D11-E11+F11-G11+H11 -> 1572.6955 | J11: =I11+-0.798 -> 1571.8975 | K11: =J11-I11 -> -0.798 | L11: =K11*Rate_Sheet!$D$11 -> -7721.6076 | M11: =Setup!$B$25 -> 2 | N11: =IF(ABS(K11)>M11,"INVESTIGATE","OK") -> OK
A12: 46304 | B12: =TEXT(A12,"YYYY-MM") -> 2026-10 | C12: =I11 -> 1572.6955 | D12: 167.566 | E12: =SUMIFS(Karigar_Ledger!$H$5:$H$56,Karigar_Ledger!$A$5:$A$56,A12) -> 252.7876 | F12: =SUMIFS(Karigar_Ledger!$J$5:$J$56,Karigar_Ledger!$A$5:$A$56,A12)+SUMIFS(Karigar_Ledger!$K$5:$K$56,Karigar_Ledger!$A$5:$A$56,A12) -> 245.80818 | G12: =SUMIFS(Sales_Register!$G$5:$G$72,Sales_Register!$A$5:$A$72,A12) -> 107.58328 | H12: =SUMIFS(Sales_Register!$N$5:$N$72,Sales_Register!$A$5:$A$72,A12) -> 0 | I12: =C12+D12-E12+F12-G12+H12 -> 1625.6988 | J12: =I12+0.675 -> 1626.3738 | K12: =J12-I12 -> 0.675 | L12: =K12*Rate_Sheet!$D$12 -> 6590.97 | M12: =Setup!$B$25 -> 2 | N12: =IF(ABS(K12)>M12,"INVESTIGATE","OK") -> OK
A13: 46305 | B13: =TEXT(A13,"YYYY-MM") -> 2026-10 | C13: =I12 -> 1625.6988 | D13: 183.235 | E13: =SUMIFS(Karigar_Ledger!$H$5:$H$56,Karigar_Ledger!$A$5:$A$56,A13) -> 185.61732 | F13: =SUMIFS(Karigar_Ledger!$J$5:$J$56,Karigar_Ledger!$A$5:$A$56,A13)+SUMIFS(Karigar_Ledger!$K$5:$K$56,Karigar_Ledger!$A$5:$A$56,A13) -> 182.05317 | G13: =SUMIFS(Sales_Register!$G$5:$G$72,Sales_Register!$A$5:$A$72,A13) -> 115.60561 | H13: =SUMIFS(Sales_Register!$N$5:$N$72,Sales_Register!$A$5:$A$72,A13) -> 0 | I13: =C13+D13-E13+F13-G13+H13 -> 1689.764 | J13: =I13+-0.05 -> 1689.714 | K13: =J13-I13 -> -0.05 | L13: =K13*Rate_Sheet!$D$13 -> -482.895 | M13: =Setup!$B$25 -> 2 | N13: =IF(ABS(K13)>M13,"INVESTIGATE","OK") -> OK
A14: 46307 | B14: =TEXT(A14,"YYYY-MM") -> 2026-10 | C14: =I13 -> 1689.764 | D14: 0 | E14: =SUMIFS(Karigar_Ledger!$H$5:$H$56,Karigar_Ledger!$A$5:$A$56,A14) -> 387.33152 | F14: =SUMIFS(Karigar_Ledger!$J$5:$J$56,Karigar_Ledger!$A$5:$A$56,A14)+SUMIFS(Karigar_Ledger!$K$5:$K$56,Karigar_Ledger!$A$5:$A$56,A14) -> 376.89838 | G14: =SUMIFS(Sales_Register!$G$5:$G$72,Sales_Register!$A$5:$A$72,A14) -> 51.2664 | H14: =SUMIFS(Sales_Register!$N$5:$N$72,Sales_Register!$A$5:$A$72,A14) -> 25.918 | I14: =C14+D14-E14+F14-G14+H14 -> 1653.9824 | J14: =I14+-0.02 -> 1653.9624 | K14: =J14-I14 -> -0.02 | L14: =K14*Rate_Sheet!$D$14 -> -192.246 | M14: =Setup!$B$25 -> 2 | N14: =IF(ABS(K14)>M14,"INVESTIGATE","OK") -> OK
A15: 46308 | B15: =TEXT(A15,"YYYY-MM") -> 2026-10 | C15: =I14 -> 1653.9824 | D15: 50.833 | E15: =SUMIFS(Karigar_Ledger!$H$5:$H$56,Karigar_Ledger!$A$5:$A$56,A15) -> 255.6382 | F15: =SUMIFS(Karigar_Ledger!$J$5:$J$56,Karigar_Ledger!$A$5:$A$56,A15)+SUMIFS(Karigar_Ledger!$K$5:$K$56,Karigar_Ledger!$A$5:$A$56,A15) -> 252.25856 | G15: =SUMIFS(Sales_Register!$G$5:$G$72,Sales_Register!$A$5:$A$72,A15) -> 98.51694 | H15: =SUMIFS(Sales_Register!$N$5:$N$72,Sales_Register!$A$5:$A$72,A15) -> 0 | I15: =C15+D15-E15+F15-G15+H15 -> 1602.9189 | J15: =I15+-4.18 -> 1598.7389 | K15: =J15-I15 -> -4.18 | L15: =K15*Rate_Sheet!$D$15 -> -40244.622 | M15: =Setup!$B$25 -> 2 | N15: =IF(ABS(K15)>M15,"INVESTIGATE","OK") -> INVESTIGATE
A16: 46309 | B16: =TEXT(A16,"YYYY-MM") -> 2026-10 | C16: =I15 -> 1602.9189 | D16: 0 | E16: =SUMIFS(Karigar_Ledger!$H$5:$H$56,Karigar_Ledger!$A$5:$A$56,A16) -> 292.19392 | F16: =SUMIFS(Karigar_Ledger!$J$5:$J$56,Karigar_Ledger!$A$5:$A$56,A16)+SUMIFS(Karigar_Ledger!$K$5:$K$56,Karigar_Ledger!$A$5:$A$56,A16) -> 279.51304 | G16: =SUMIFS(Sales_Register!$G$5:$G$72,Sales_Register!$A$5:$A$72,A16) -> 88.185152 | H16: =SUMIFS(Sales_Register!$N$5:$N$72,Sales_Register!$A$5:$A$72,A16) -> 0 | I16: =C16+D16-E16+F16-G16+H16 -> 1502.0528 | J16: =I16+4.05 -> 1506.1028 | K16: =J16-I16 -> 4.05 | L16: =K16*Rate_Sheet!$D$16 -> 38931.84 | M16: =Setup!$B$25 -> 2 | N16: =IF(ABS(K16)>M16,"INVESTIGATE","OK") -> INVESTIGATE
A17: 46310 | B17: =TEXT(A17,"YYYY-MM") -> 2026-10 | C17: =I16 -> 1502.0528 | D17: 127.377 | E17: =SUMIFS(Karigar_Ledger!$H$5:$H$56,Karigar_Ledger!$A$5:$A$56,A17) -> 496.24666 | F17: =SUMIFS(Karigar_Ledger!$J$5:$J$56,Karigar_Ledger!$A$5:$A$56,A17)+SUMIFS(Karigar_Ledger!$K$5:$K$56,Karigar_Ledger!$A$5:$A$56,A17) -> 485.53261 | G17: =SUMIFS(Sales_Register!$G$5:$G$72,Sales_Register!$A$5:$A$72,A17) -> 135.5396 | H17: =SUMIFS(Sales_Register!$N$5:$N$72,Sales_Register!$A$5:$A$72,A17) -> 31.004 | I17: =C17+D17-E17+F17-G17+H17 -> 1514.1802 | J17: =I17+0.141 -> 1514.3212 | K17: =J17-I17 -> 0.141 | L17: =K17*Rate_Sheet!$D$17 -> 1354.4319 | M17: =Setup!$B$25 -> 2 | N17: =IF(ABS(K17)>M17,"INVESTIGATE","OK") -> OK
A18: 46311 | B18: =TEXT(A18,"YYYY-MM") -> 2026-10 | C18: =I17 -> 1514.1802 | D18: 205.425 | E18: =SUMIFS(Karigar_Ledger!$H$5:$H$56,Karigar_Ledger!$A$5:$A$56,A18) -> 216.26302 | F18: =SUMIFS(Karigar_Ledger!$J$5:$J$56,Karigar_Ledger!$A$5:$A$56,A18)+SUMIFS(Karigar_Ledger!$K$5:$K$56,Karigar_Ledger!$A$5:$A$56,A18) -> 211.67884 | G18: =SUMIFS(Sales_Register!$G$5:$G$72,Sales_Register!$A$5:$A$72,A18) -> 66.182486 | H18: =SUMIFS(Sales_Register!$N$5:$N$72,Sales_Register!$A$5:$A$72,A18) -> 16.94 | I18: =C18+D18-E18+F18-G18+H18 -> 1665.7785 | J18: =I18+0.134 -> 1665.9125 | K18: =J18-I18 -> 0.134 | L18: =K18*Rate_Sheet!$D$18 -> 1297.0128 | M18: =Setup!$B$25 -> 2 | N18: =IF(ABS(K18)>M18,"INVESTIGATE","OK") -> OK
A19: 46312 | B19: =TEXT(A19,"YYYY-MM") -> 2026-10 | C19: =I18 -> 1665.7785 | D19: 0 | E19: =SUMIFS(Karigar_Ledger!$H$5:$H$56,Karigar_Ledger!$A$5:$A$56,A19) -> 366.68762 | F19: =SUMIFS(Karigar_Ledger!$J$5:$J$56,Karigar_Ledger!$A$5:$A$56,A19)+SUMIFS(Karigar_Ledger!$K$5:$K$56,Karigar_Ledger!$A$5:$A$56,A19) -> 359.17441 | G19: =SUMIFS(Sales_Register!$G$5:$G$72,Sales_Register!$A$5:$A$72,A19) -> 26.260458 | H19: =SUMIFS(Sales_Register!$N$5:$N$72,Sales_Register!$A$5:$A$72,A19) -> 0 | I19: =C19+D19-E19+F19-G19+H19 -> 1632.0048 | J19: =I19+0.419 -> 1632.4238 | K19: =J19-I19 -> 0.419 | L19: =K19*Rate_Sheet!$D$19 -> 4066.814 | M19: =Setup!$B$25 -> 2 | N19: =IF(ABS(K19)>M19,"INVESTIGATE","OK") -> OK
A20: 46314 | B20: =TEXT(A20,"YYYY-MM") -> 2026-10 | C20: =I19 -> 1632.0048 | D20: 0 | E20: =SUMIFS(Karigar_Ledger!$H$5:$H$56,Karigar_Ledger!$A$5:$A$56,A20) -> 294.44912 | F20: =SUMIFS(Karigar_Ledger!$J$5:$J$56,Karigar_Ledger!$A$5:$A$56,A20)+SUMIFS(Karigar_Ledger!$K$5:$K$56,Karigar_Ledger!$A$5:$A$56,A20) -> 283.07602 | G20: =SUMIFS(Sales_Register!$G$5:$G$72,Sales_Register!$A$5:$A$72,A20) -> 36.531912 | H20: =SUMIFS(Sales_Register!$N$5:$N$72,Sales_Register!$A$5:$A$72,A20) -> 0 | I20: =C20+D20-E20+F20-G20+H20 -> 1584.0998 | J20: =I20+0.574 -> 1584.6738 | K20: =J20-I20 -> 0.574 | L20: =K20*Rate_Sheet!$D$20 -> 5517.9768 | M20: =Setup!$B$25 -> 2 | N20: =IF(ABS(K20)>M20,"INVESTIGATE","OK") -> OK
A21: 46315 | B21: =TEXT(A21,"YYYY-MM") -> 2026-10 | C21: =I20 -> 1584.0998 | D21: 13.712 | E21: =SUMIFS(Karigar_Ledger!$H$5:$H$56,Karigar_Ledger!$A$5:$A$56,A21) -> 502.18876 | F21: =SUMIFS(Karigar_Ledger!$J$5:$J$56,Karigar_Ledger!$A$5:$A$56,A21)+SUMIFS(Karigar_Ledger!$K$5:$K$56,Karigar_Ledger!$A$5:$A$56,A21) -> 482.49162 | G21: =SUMIFS(Sales_Register!$G$5:$G$72,Sales_Register!$A$5:$A$72,A21) -> 65.107102 | H21: =SUMIFS(Sales_Register!$N$5:$N$72,Sales_Register!$A$5:$A$72,A21) -> 18.663 | I21: =C21+D21-E21+F21-G21+H21 -> 1531.6706 | J21: =I21+0.956 -> 1532.6266 | K21: =J21-I21 -> 0.956 | L21: =K21*Rate_Sheet!$D$21 -> 9264.5004 | M21: =Setup!$B$25 -> 2 | N21: =IF(ABS(K21)>M21,"INVESTIGATE","OK") -> OK
A22: 46316 | B22: =TEXT(A22,"YYYY-MM") -> 2026-10 | C22: =I21 -> 1531.6706 | D22: 0 | E22: =SUMIFS(Karigar_Ledger!$H$5:$H$56,Karigar_Ledger!$A$5:$A$56,A22) -> 400.03918 | F22: =SUMIFS(Karigar_Ledger!$J$5:$J$56,Karigar_Ledger!$A$5:$A$56,A22)+SUMIFS(Karigar_Ledger!$K$5:$K$56,Karigar_Ledger!$A$5:$A$56,A22) -> 390.7439 | G22: =SUMIFS(Sales_Register!$G$5:$G$72,Sales_Register!$A$5:$A$72,A22) -> 100.17742 | H22: =SUMIFS(Sales_Register!$N$5:$N$72,Sales_Register!$A$5:$A$72,A22) -> 4.75 | I22: =C22+D22-E22+F22-G22+H22 -> 1426.9479 | J22: =I22+-2.86 -> 1424.0879 | K22: =J22-I22 -> -2.86 | L22: =K22*Rate_Sheet!$D$22 -> -27917.318 | M22: =Setup!$B$25 -> 2 | N22: =IF(ABS(K22)>M22,"INVESTIGATE","OK") -> INVESTIGATE
A23: 46317 | B23: =TEXT(A23,"YYYY-MM") -> 2026-10 | C23: =I22 -> 1426.9479 | D23: 0 | E23: =SUMIFS(Karigar_Ledger!$H$5:$H$56,Karigar_Ledger!$A$5:$A$56,A23) -> 326.92223 | F23: =SUMIFS(Karigar_Ledger!$J$5:$J$56,Karigar_Ledger!$A$5:$A$56,A23)+SUMIFS(Karigar_Ledger!$K$5:$K$56,Karigar_Ledger!$A$5:$A$56,A23) -> 316.75681 | G23: =SUMIFS(Sales_Register!$G$5:$G$72,Sales_Register!$A$5:$A$72,A23) -> 41.42856 | H23: =SUMIFS(Sales_Register!$N$5:$N$72,Sales_Register!$A$5:$A$72,A23) -> 0 | I23: =C23+D23-E23+F23-G23+H23 -> 1375.3539 | J23: =I23+-0.156 -> 1375.1979 | K23: =J23-I23 -> -0.156 | L23: =K23*Rate_Sheet!$D$23 -> -1517.0688 | M23: =Setup!$B$25 -> 2 | N23: =IF(ABS(K23)>M23,"INVESTIGATE","OK") -> OK
A24: 46318 | B24: =TEXT(A24,"YYYY-MM") -> 2026-10 | C24: =I23 -> 1375.3539 | D24: 0 | E24: =SUMIFS(Karigar_Ledger!$H$5:$H$56,Karigar_Ledger!$A$5:$A$56,A24) -> 133.69295 | F24: =SUMIFS(Karigar_Ledger!$J$5:$J$56,Karigar_Ledger!$A$5:$A$56,A24)+SUMIFS(Karigar_Ledger!$K$5:$K$56,Karigar_Ledger!$A$5:$A$56,A24) -> 131.05966 | G24: =SUMIFS(Sales_Register!$G$5:$G$72,Sales_Register!$A$5:$A$72,A24) -> 68.216922 | H24: =SUMIFS(Sales_Register!$N$5:$N$72,Sales_Register!$A$5:$A$72,A24) -> 10.786 | I24: =C24+D24-E24+F24-G24+H24 -> 1315.2897 | J24: =I24+0.652 -> 1315.9417 | K24: =J24-I24 -> 0.652 | L24: =K24*Rate_Sheet!$D$24 -> 6329.29 | M24: =Setup!$B$25 -> 2 | N24: =IF(ABS(K24)>M24,"INVESTIGATE","OK") -> OK
A25: 46319 | B25: =TEXT(A25,"YYYY-MM") -> 2026-10 | C25: =I24 -> 1315.2897 | D25: 188.464 | E25: =SUMIFS(Karigar_Ledger!$H$5:$H$56,Karigar_Ledger!$A$5:$A$56,A25) -> 203.07537 | F25: =SUMIFS(Karigar_Ledger!$J$5:$J$56,Karigar_Ledger!$A$5:$A$56,A25)+SUMIFS(Karigar_Ledger!$K$5:$K$56,Karigar_Ledger!$A$5:$A$56,A25) -> 197.80168 | G25: =SUMIFS(Sales_Register!$G$5:$G$72,Sales_Register!$A$5:$A$72,A25) -> 78.957368 | H25: =SUMIFS(Sales_Register!$N$5:$N$72,Sales_Register!$A$5:$A$72,A25) -> 13.473 | I25: =C25+D25-E25+F25-G25+H25 -> 1432.9956 | J25: =I25+1.4 -> 1434.3956 | K25: =J25-I25 -> 1.4 | L25: =K25*Rate_Sheet!$D$25 -> 13517 | M25: =Setup!$B$25 -> 2 | N25: =IF(ABS(K25)>M25,"INVESTIGATE","OK") -> OK
A26: 46321 | B26: =TEXT(A26,"YYYY-MM") -> 2026-10 | C26: =I25 -> 1432.9956 | D26: 0 | E26: =SUMIFS(Karigar_Ledger!$H$5:$H$56,Karigar_Ledger!$A$5:$A$56,A26) -> 311.53252 | F26: =SUMIFS(Karigar_Ledger!$J$5:$J$56,Karigar_Ledger!$A$5:$A$56,A26)+SUMIFS(Karigar_Ledger!$K$5:$K$56,Karigar_Ledger!$A$5:$A$56,A26) -> 300.16454 | G26: =SUMIFS(Sales_Register!$G$5:$G$72,Sales_Register!$A$5:$A$72,A26) -> 96.241372 | H26: =SUMIFS(Sales_Register!$N$5:$N$72,Sales_Register!$A$5:$A$72,A26) -> 14.837 | I26: =C26+D26-E26+F26-G26+H26 -> 1340.2233 | J26: =I26+-1.091 -> 1339.1323 | K26: =J26-I26 -> -1.091 | L26: =K26*Rate_Sheet!$D$26 -> -10658.197 | M26: =Setup!$B$25 -> 2 | N26: =IF(ABS(K26)>M26,"INVESTIGATE","OK") -> OK
A28: Issues, returns, sales and old gold all pull from their source sheets by SUMIFS on date, so the ledger cannot drift from the registers.

Sheet Daily_Recon
A1: Daily Reconciliation
A2: Change the date in the yellow cell. Everything recalculates.
A4: Reporting date | B4: 46308
A6: 1. STOCK POSITION
A7: Opening book (g fine) | B7: =SUMIFS(Metal_Ledger!$C$5:$C$26,Metal_Ledger!$A$5:$A$26,$B$4) -> 1653.9824
A8: Closing book (g fine) | B8: =SUMIFS(Metal_Ledger!$I$5:$I$26,Metal_Ledger!$A$5:$A$26,$B$4) -> 1602.9189
A9: Physical counted (g fine) | B9: =SUMIFS(Metal_Ledger!$J$5:$J$26,Metal_Ledger!$A$5:$A$26,$B$4) -> 1598.7389
A10: Variance (g fine) | B10: =SUMIFS(Metal_Ledger!$K$5:$K$26,Metal_Ledger!$A$5:$A$26,$B$4) -> -4.18 | D10: Physical minus book. Negative means metal is missing.
A11: Variance at today's spot (₹) | B11: =SUMIFS(Metal_Ledger!$L$5:$L$26,Metal_Ledger!$A$5:$A$26,$B$4) -> -40244.622
A12: Tolerance (g fine) | B12: =Setup!$B$25 -> 2
A13: Verdict | B13: =IF(ABS(B10)>B12,"INVESTIGATE","WITHIN TOLERANCE") -> INVESTIGATE
A15: 2. METAL OUT WITH KARIGARS
A16: Issued today (g fine) | B16: =SUMIFS(Karigar_Ledger!$H$5:$H$56,Karigar_Ledger!$A$5:$A$56,$B$4) -> 255.6382
A17: Returned today, finished + scrap (g fine) | B17: =SUMIFS(Karigar_Ledger!$J$5:$J$56,Karigar_Ledger!$A$5:$A$56,$B$4)+SUMIFS(Karigar_Ledger!$K$5:$K$56,Karigar_Ledger!$A$5:$A$56,$B$4) -> 252.25856
A18: Wastage today (g fine) | B18: =SUMIFS(Karigar_Ledger!$L$5:$L$56,Karigar_Ledger!$A$5:$A$56,$B$4) -> 3.379636
A19: Cumulative out with karigars to date (g fine) | B19: =SUMIFS(Karigar_Ledger!$H$5:$H$56,Karigar_Ledger!$A$5:$A$56,"<="&$B$4)-SUMIFS(Karigar_Ledger!$J$5:$J$56,Karigar_Ledger!$A$5:$A$56,"<="&$B$4)-SUMIFS(Karigar_Ledger!$K$5:$K$56,Karigar_Ledger!$A$5:$A$56,"<="&$B$4) -> 105.26112 | D19: Unreturned metal. This is the shop's real exposure to its karigars.
A20: Lines over wastage norm today | B20: =COUNTIFS(Karigar_Ledger!$A$5:$A$56,$B$4,Karigar_Ledger!$P$5:$P$56,"OVER NORM") -> 0
A22: 3. RATE POSITION
A23: Spot 24K (₹/10g) | B23: =SUMIFS(Rate_Sheet!$C$5:$C$26,Rate_Sheet!$A$5:$A$26,$B$4) -> 96279
A24: Spot fine (₹/g) | B24: =SUMIFS(Rate_Sheet!$D$5:$D$26,Rate_Sheet!$A$5:$A$26,$B$4) -> 9627.9
A25: Board rate implied fine (₹/g) | B25: =SUMIFS(Rate_Sheet!$F$5:$F$26,Rate_Sheet!$A$5:$A$26,$B$4) -> 9674.4323
A26: Drift (₹/g fine) | B26: =SUMIFS(Rate_Sheet!$G$5:$G$26,Rate_Sheet!$A$5:$A$26,$B$4) -> 46.532314 | D26: Board minus spot. Negative means selling below replacement cost.
A27: Fine gold sold today (g) | B27: =SUMIFS(Sales_Register!$G$5:$G$72,Sales_Register!$A$5:$A$72,$B$4) -> 98.51694
A28: Cost of the drift today (₹) | B28: =B27*B26 -> 4584.2212 | D28: Grams sold multiplied by the per-gram gap. Lost on today's tickets.
A29: Verdict | B29: =IF(ABS(B26)>Setup!$B$26,"REPRICE BOARD NOW","BOARD RATE OK") -> BOARD RATE OK
A31: 4. MAKING CHARGE LEAKAGE
A32: MC list today (₹) | B32: =SUMIFS(Sales_Register!$J$5:$J$72,Sales_Register!$A$5:$A$72,$B$4) -> 60408.95
A33: MC realised today (₹) | B33: =SUMIFS(Sales_Register!$L$5:$L$72,Sales_Register!$A$5:$A$72,$B$4) -> 53939.06
A34: MC given away today (₹) | B34: =SUMIFS(Sales_Register!$M$5:$M$72,Sales_Register!$A$5:$A$72,$B$4) -> 6469.89 | D34: Pure margin handed over at the counter.
A35: Realisation % | B35: =IFERROR(B33/B32,0) -> 0.89289849
A36: Floor | B36: =Setup!$B$27 -> 0.85
A37: Verdict | B37: =IF(B35<B36,"DISCOUNTING TOO DEEP","OK") -> OK
A39: 5. DAY SUMMARY
A40: Invoices today | B40: =COUNTIFS(Sales_Register!$A$5:$A$72,$B$4) -> 3
A41: Net invoiced value (₹) | B41: =SUMIFS(Sales_Register!$P$5:$P$72,Sales_Register!$A$5:$A$72,$B$4) -> 1007034.5
A42: Metal value billed (₹) | B42: =SUMIFS(Sales_Register!$I$5:$I$72,Sales_Register!$A$5:$A$72,$B$4) -> 953095.47
A43: Old gold credited (₹) | B43: =SUMIFS(Sales_Register!$O$5:$O$72,Sales_Register!$A$5:$A$72,$B$4) -> 0

Sheet Monthly_Analysis
A1: Monthly Analysis
A2: Rollup by month. Leakage and variance are the two to watch.
A4: Month | B4: Invoices | C4: Fine gold sold (g) | D4: Net invoiced (₹) | E4: MC list (₹) | F4: MC realised (₹) | G4: MC given away (₹) | H4: Realisation % | I4: Gross variance (g fine) | J4: Days over tolerance | K4: Karigar wastage (g fine) | L4: Lines over norm
